Exception in thread Learner:
Traceback (most recent call last):
  File "/usr/lib/python3.13/threading.py", line 1041, in _bootstrap_inner
    self.run()
    ~~~~~~~~^^
  File "/usr/lib/python3.13/threading.py", line 992, in run
    self._target(*self._args, **self._kwargs)
    ~~~~~~~~~~~~^^^^^^^^^^^^^^^^^^^^^^^^^^^^^
  File "/workspace/tools/trainer.py", line 179, in _learner_loop
    loss = self.spine.train_step(x, x)
  File "/workspace/spine/neural_spine.py", line 62, in train_step
    for name, module in self.modules.items():
                        ~~~~~~~~~~~~~~~~~~^^
RuntimeError: dictionary changed size during iteration
